<?xml version='1.0'?>

<robot name="diffrobot">

  
<link name="robot_footprint">
</link>

    
    <joint name="robot_footprint_joint" type="fixed">
        <origin xyz="0 0 0.0" rpy="0 0 0" />
        <parent link="robot_footprint"/>
        <child link="base_link"/>
    </joint>

    <link name="base_link">
        <inertial>
            <origin xyz="0.0 0.0 0.0" rpy="0.0 0.0 0.0"/>
            <mass value="5.0"/>
            <inertia ixx="0.0" ixy="0.0" ixz="0.0" iyy="0.0" iyz="0.0" izz="0.0"/>
        </inertial>
        <visual name="base_link_visual">
            <origin xyz="0.0 0.0 0.0" rpy="0.0 0.0 0.0"/>
            <geometry>
                <box size="0.4 0.2 0.1"/>
            </geometry>
            <material name="">
                <color rgba="0.0 0.0 1.0 1.0"/>
                <texture filename=""/>
            </material>
        </visual>
        <collision>
            <origin xyz="0.0 0.0 0.0" rpy="0.0 0.0 0.0"/>
            <geometry>
                <box size="0.4 0.2 0.1"/>
            </geometry>
        </collision>
    </link>

    <link name="left_wheel">
        <inertial>
            <origin xyz="0.0 0.0 0.0" rpy="0.0 1.5707 1.5707"/>
            <mass value="5.0"/>
            <inertia ixx="0.1" ixy="0.0" ixz="0.0" iyy="0.1" iyz="0.0" izz="0.1"/>
        </inertial>
        <visual name="left_wheel_visual">
            <origin xyz="0.0 0.0 0.0" rpy="0.0 0.0 0.0"/>
            <geometry>
                <cylinder radius="0.1" length="0.05"/>
            </geometry>
        </visual>
        <collision name='left_wheel_collision'>
            <origin xyz="0.0 0.0 0.0" rpy="0.0 0.0 0.0"/>
            <geometry>
                <cylinder radius="0.1" length="0.05"/>
            </geometry>
        </collision>
    </link>

    <link name="right_wheel">
        <inertial>
            <origin xyz="0.0 0.0 0.0" rpy="0.0 0.0 0.0"/>
            <mass value="5.0"/>
            <inertia ixx="0.1" ixy="0.0" ixz="0.0" iyy="0.1" iyz="0.0" izz="0.1"/>
        </inertial>
        <visual name="right_wheel_visual">
            <origin xyz="0.0 0.0 0.0" rpy="0.0 0.0 0.0"/>
            <geometry>
                <cylinder radius="0.1" length="0.05"/>
            </geometry>
        </visual>
        <collision name='right_wheel_collision'>
            <origin xyz="0.0 0.0 0.0" rpy="0.0 0.0 0.0"/>
            <geometry>
                <cylinder radius="0.1" length="0.05"/>
            </geometry>
        </collision>
    </link>

    <joint name="wheel_left_joint" type="continuous">
        <origin xyz="0.0 0.15 0.0" rpy="0.0 1.5705 1.5705"/>
        <parent link="base_link"/>
        <child link="left_wheel"/>
        <axis xyz="0.0 0.0 1.0"/>

    </joint>


    <joint name="wheel_right_joint" type="continuous">
        <origin xyz="0.0 -0.15 0.0" rpy="0.0 1.5705 1.5705"/>
        <parent link="base_link"/>
        <child link="right_wheel"/>
        <axis xyz="0.0 0.0 1.0"/>

    </joint>


    <link name="front_caster">
        <inertial>
            <origin xyz="0.0 0.0 0.0" rpy="0.0 0.0 0.0"/>
            <mass value="0.2"/>
            <inertia ixx="0.002526666666667" ixy="0" ixz="0" iyy="0.002526666666667" iyz="0" izz="0.005"/>
        </inertial>
        <visual name="front_caster_visual">
            <origin xyz="0.0 0.0 0.0" rpy="0.0 0.0 0.0"/>
            <geometry>
                <sphere radius="0.0499"/>
            </geometry>
            <material name="">
                <color rgba="1.0 1.0 1.0 1.0"/>
                <texture filename=""/>
            </material>
        </visual>
        <collision>
            <origin xyz="0.0 0.0 0.0" rpy="0.0 0.0 0.0"/>
            <geometry>
                <sphere radius="0.0499"/>
            </geometry>
        </collision>
    </link>

    <joint name="front_caster_joint" type="fixed">
        <origin xyz="0.15 0.0 -0.05" rpy="0.0 0.0 0.0"/>
        <parent link="base_link"/>
        <child link="front_caster"/>
        <axis xyz="0.0 0.0 0.0"/>


    </joint>

    <gazebo reference="front_caster_joint">
        <preserveFixedJoint>true</preserveFixedJoint>
    </gazebo>
    <link name="back_caster">
            <inertial>
                <origin xyz="0.0 0.0 0.0" rpy="0.0 0.0 0.0"/>
                <mass value="0.2"/>
                <inertia ixx="0.002526666666667" ixy="0" ixz="0" iyy="0.002526666666667" iyz="0" izz="0.005"/>
            </inertial>
            <visual name="back_caster_visual">
                <origin xyz="0.0 0.0 0.0" rpy="0.0 0.0 0.0"/>
                <geometry>
                    <sphere radius="0.0499"/>
                </geometry>
                <material name="">
                    <color rgba="1.0 1.0 1.0 1.0"/>
                    <texture filename=""/>
                </material>
            </visual>
            <collision>
                <origin xyz="0.0 0.0 0.0" rpy="0.0 0.0 0.0"/>
                <geometry>
                    <sphere radius="0.0499"/>
                </geometry>
            </collision>
    </link>

    <joint name="back_caster_joint" type="fixed">
        <origin xyz="-0.15 0.0 -0.05" rpy="0.0 0.0 0.0"/>
        <parent link="base_link"/>
        <child link="back_caster"/>
        <axis xyz="0.0 0.0 0.0"/>



    </joint>
    <gazebo reference="back_caster_joint">
        <preserveFixedJoint>true</preserveFixedJoint>
    </gazebo>

    <link name="lidar_link">
        <inertial>
            <origin xyz="0.0 0.0 0.0" rpy="0.0 0.0 0.0"/>
            <mass value="0.1"/>
            <inertia ixx="0.002526666666667" ixy="0" ixz="0" iyy="0.002526666666667" iyz="0" izz="0.005"/>
        </inertial>
        <visual name="lidar_link_visual">
            <origin xyz="0.0 0.0 0.0" rpy="0.0 0.0 0.0"/>
            <geometry>
                <mesh filename="package://diffrobot_description/meshes/lidar_link.STL"/>
            </geometry>
            <material name="">
                <color rgba="1.0 0.0 0.0 1.0"/>
                <texture filename=""/>
            </material>
        </visual>
        <collision>
            <origin xyz="0.0 0.0 0.0" rpy="0.0 0.0 0.0"/>
            <geometry>
                <box size="0.1 0.1 0.1"/>
            </geometry>
        </collision>
    </link>

    <joint name="lidar_joint" type="fixed">
        <origin xyz="0.11 0.0 0.12" rpy="1.5708 0.0 1.5708"/>
        <parent link="base_link"/>
        <child link="lidar_link"/>
    </joint>

<gazebo reference="lidar_joint">
    <preserveFixedJoint>true</preserveFixedJoint>
</gazebo>

    <link name="laser">
        <inertial>
            <origin xyz="0.0 0.0 0.0" rpy="0.0 0.0 0.0"/>
            <mass value="0.1"/>
            <inertia ixx="0.002526666666667" ixy="0" ixz="0" iyy="0.002526666666667" iyz="0" izz="0.005"/>
        </inertial>
        
    </link>


    <joint name="laser_data_joint" type="fixed">
        <origin xyz="0.0 0.0 0.0" rpy="0.0 -1.5708 -1.5708"/>
        <parent link="lidar_link"/>
        <child link="laser"/>
    </joint>
    <gazebo reference="laser_data_joint">
        <preserveFixedJoint>true</preserveFixedJoint>
    </gazebo>


    <link name="diffrobot/laser/rp_laser">
        <inertial>
            <origin xyz="0.0 0.0 0.0" rpy="0.0 0.0 0.0"/>
            <mass value="0.2"/>
            <inertia ixx="0.002526666666667" ixy="0" ixz="0" iyy="0.002526666666667" iyz="0" izz="0.005"/>
        </inertial>
    </link>


    <joint name="rp_laser_joint" type="fixed">
        <origin xyz="0.0 0.0 0.0" rpy="0.0 0 0"/>
        <parent link="laser"/>
        <child link="diffrobot/laser/rp_laser"/>
    </joint>

    <gazebo reference="rp_laser_joint">
        <preserveFixedJoint>true</preserveFixedJoint>
    </gazebo>

    <link name="imu_link">
        <inertial>
            <origin xyz="0.0 0.0 0.0" rpy="0.0 0.0 0.0"/>
            <mass value="0.0"/>
            <inertia ixx="0.002526666666667" ixy="0" ixz="0" iyy="0.002526666666667" iyz="0" izz="0.005"/>
        </inertial>
        <visual name="">
            <origin xyz="0.0 0.0 0.0" rpy="0.0 0.0 0.0"/>
            <geometry>
                <box size="0.02 0.02 0.02"/>
            </geometry>
            <material name="">
                <color rgba="1.0 0.0 0.0 1.0"/>
                <texture filename=""/>
            </material>
        </visual>
        <collision>
            <origin xyz="0.0 0.0 0.0" rpy="0.0 0.0 0.0"/>
            <geometry>
                <box size="0.02 0.02 0.02"/>
            </geometry>
        </collision>
    </link>
    <joint name="imu_joint" type="fixed">
        <origin xyz="0.0 0.0 0.0" rpy="0.0 0.0 0.0"/>
        <parent link="base_link"/>
        <child link="imu_link"/>
    </joint>





<!-- Materials and friction -->

<gazebo reference="base_link">
    <visual>
        <material> <!-- Blue -->
            <ambient>0.0 0.0 1.0 1.0</ambient>
            <diffuse>0.0 0.0 1.0 1.0</diffuse>
            <specular>0.0 0.0 0.0 1.0</specular>
            <emissive>0.0 0.0 0.0 1.0</emissive>
        </material>
    </visual>
    
</gazebo>

<gazebo reference="right_wheel">
    <visual>
        <material> <!-- Gray -->
            <ambient>0.25 0.25 0.25 1.0</ambient>
            <diffuse>0.25 0.25 0.25 1.0</diffuse>
            <specular>0.0 0.0 0.0 1.0</specular>
            <emissive>0.0 0.0 0.0 1.0</emissive>
        </material>
    </visual>
    <collision>
        <surface>
            <friction>
                <ode>
                    <mu>0.5</mu>
                    <mu2>0.5</mu2>
                </ode>
            </friction>
        </surface>
    </collision>
</gazebo>
<gazebo reference="left_wheel">
    <visual>
        <material> <!-- Black -->
            <ambient>0.1 0.1 0.1 1.0</ambient>
            <diffuse>0.1 0.1 0.1 1.0</diffuse>
            <specular>0.0 0.0 0.0 1.0</specular>
            <emissive>0.0 0.0 0.0 1.0</emissive>
        </material>
    </visual>
    <collision>
        <surface>
            <friction>
                <ode>
                    <mu>0.5</mu>
                    <mu2>0.5</mu2>
                </ode>
            </friction>
        </surface>
    </collision>
</gazebo>
<gazebo reference="front_caster">
    <visual>
        <material> <!-- Black -->
            <ambient>0.1 0.1 0.1 1.0</ambient>
            <diffuse>0.1 0.1 0.1 1.0</diffuse>
            <specular>0.0 0.0 0.0 1.0</specular>
            <emissive>0.0 0.0 0.0 1.0</emissive>
        </material>
    </visual>
    <collision>
        <surface>
            <friction>
                <ode>
                    <mu>1.0</mu>
                    <mu2>1.0</mu2>
                </ode>
            </friction>
        </surface>
    </collision>
</gazebo>

<gazebo reference="back_caster">
    <visual>
        <material> <!-- Black -->
            <ambient>0.1 0.1 0.1 1.0</ambient>
            <diffuse>0.1 0.1 0.1 1.0</diffuse>
            <specular>0.0 0.0 0.0 1.0</specular>
            <emissive>0.0 0.0 0.0 1.0</emissive>
        </material>
    </visual>
    <collision>
        <surface>
            <friction>
                <ode>
                    <mu>1.0</mu>
                    <mu2>1.0</mu2>
                </ode>
            </friction>
        </surface>
    </collision>
</gazebo>

<gazebo reference="lidar_link">
    <visual>
        <material> <!-- Black -->
            <ambient>0.1 0.1 0.1 1.0</ambient>
            <diffuse>0.1 0.1 0.1 1.0</diffuse>
            <specular>0.0 0.0 0.0 1.0</specular>
            <emissive>0.0 0.0 0.0 1.0</emissive>
        </material>
    </visual>
</gazebo>


<!-- Differential Drive Plugin -->
<gazebo>
    <plugin
        filename="libignition-gazebo-diff-drive-system.so"
        name="ignition::gazebo::systems::DiffDrive">
        <left_joint>wheel_left_joint</left_joint>
        <right_joint>wheel_right_joint</right_joint>
        <wheel_separation>0.2</wheel_separation>
        <wheel_radius>0.1</wheel_radius>
        <odom_publish_frequency>20</odom_publish_frequency>
        <topic>cmd_vel</topic>
        <odom_topic>odom</odom_topic>
        <tf_topic>tf</tf_topic>
        <frame_id>odom</frame_id>
        <child_frame_id>robot_footprint</child_frame_id>
    </plugin>
</gazebo>


<!-- Laser Scanner Plugin -->
<gazebo>
    <plugin
      filename="libignition-gazebo-sensors-system"
      name="ignition::gazebo::systems::Sensors">
      <!-- use ogre2 if ogre v2.x is installed, otherwise use ogre -->
      <render_engine>ogre2</render_engine>
    </plugin>
</gazebo>
<gazebo reference="laser">
    <sensor type="gpu_lidar" name="rp_laser">
        <pose relative_to='laser'>0 0 0 0 0 0</pose>
        <always_on>1</always_on>
        <visualize>true</visualize>
        <update_rate>20</update_rate>
        <topic>scan</topic>
        <ray>
            <scan>
                <horizontal>
                    <samples>720</samples>
                    <resolution>1</resolution>
                    <min_angle>-1.570796</min_angle>
                    <max_angle>1.570796</max_angle>
                </horizontal>
            </scan>
            <range>
                <min>0.20</min>
                <max>10.0</max>
                <resolution>0.01</resolution>
            </range>
            <noise>
                <type>gaussian</type>
                <mean>0.0</mean>
                <stddev>0.01</stddev>
            </noise>
        </ray>
    </sensor>
</gazebo>

</robot>